Workbook

Sheet ورودی محاسبات صورت وضعیت
A1: راهنمای محاسبه صورت وضعیت تایید شده پیمانکار با در نظر گرفتن مفاد بند 1-2-7- 5 (توجه: فصول مربوط به کارهای فولادی در صورت ساخت در کارخانه و فولادی سنگین در صورت ساخت در کارخانه در جدول زیر وارد می‌شوند.)
A2: ردیف | B2: فهارس بها | C2: مبلغ صورت وضعیت تایید شده پیمانکار (ریال) | D2: مبلغ صورت وضعیت تایید شده پیمانکار (جمع فصول بدون ضریب پیشنهادی پیمانکار) | E2: مبلغ خرید تجهیزات خاص (در صورت وجود) | F2: ضریب کاهشی تجهیزات خاص | G2: مبلغ فصول به تفکیک (بدون ضریب فصل) | Q2: میلغ صورت وضعیت اصلاح شده با در نظر گرفتن مفاد بند 1-2-7-5 (ریال) | R2: فهرست‌های غیر قابل استفاده در پروژه را hide کنید.
A3: 1 | B3: فهرست بهای رشته انتقال و توزيع آب روستايی | F3: 0.2 | G3: 2 | H3: 3 | I3: 4 | J3: 8 | K3: 9 | L3: 12 | M3: 14 | N3: 15 | O3: 16 | P3: 17 | Q3: =D3-(1-F3)*E3-0.6*(G4+H4+I4+J4+K4+N4+O4+P4)-0.8*M4-0.5*L4 -> 0
A5: 2 | B5: فهرست بهای رشته شبكه جمع آوری و انتقال فاضلاب | C5: 62585074025 | D5: 5.945582e+10 | F5: 0.2 | G5: 9 | H5: 12 | I5: 14 | J5: 15 | K5: 17 | L5: 18 | Q5: =D5-(1-F5)*E5-0.8*(I6+J6+K6+L6)-0.8*H6-0.5*G6 -> 3.3164224e+10
H6: 16520025430 | I6: 6758222055 | J6: 9586248220
A7: 3 | B7: فهرست بهای رشته خطوط انتقال آب | F7: 0.2 | G7: 12 | H7: 14 | I7: 15 | J7: 16 | K7: 17 | L7: 18 | Q7: =D7-(1-F7)*E7-0.8*(I8+J8+K8+L8)-0.8*H8-0.5*G8 -> 0
A9: 4 | B9: فهرست بهای رشته شبكه توزيع آب | F9: 0.2 | G9: 9 | H9: 11 | I9: 12 | J9: 13 | K9: 14 | Q9: =D9-(1-F9)*E9-0.8*(I10+J10+K10)-0.8*H10-0.5*G10 -> 0
A11: 5 | B11: فهرست بهای رشته راهداری | F11: 0.2 | G11: 10 | H11: 15 | I11: 17 | J11: 18 | K11: 20 | Q11: =D11-(1-F11)*E11-0.8*(I12+J12)-0.8*K12-0.5*G12-0.55*H12 -> 0
A13: 6 | B13: فهرست بهای رشته راه، راه آهن و باند فرودگاه (پروژه بهسازی نوع یک و دو) | F13: 0.2 | G13: 10 | H13: 15 | I13: 17 | J13: 20 | K13: 22 | Q13: =D13-(1-F13)*E13-0.8*(I14+K14)-0.8*J14-0.5*G14-0.65*H14 -> 0
A15: 7 | B15: فهرست بهای رشته راه، راه آهن و باند فرودگاه | C15: 130852497020 | D15: 104681997616 | F15: 0.2 | G15: 10 | H15: 15 | I15: 17 | J15: 20 | K15: 22 | Q15: =D15-(1-F15)*E15-0.8*(I16+K16)-0.8*J16-0.5*G16-0.55*H16 -> 9.5061354e+10
J16: 12025804632
A17: 8 | B17: فهرست بهای آبخیزداری و منابع طبیعی | F17: 0.2 | G17: 10 | H17: 14 | I17: 15 | Q17: =D17-(1-F17)*E17-0.8*(H18+I18)-0.5*G18 -> 0
A19: 9 | B19: فهرست بهای رشته سدسازی | F19: 0.2 | G19: 5 | H19: 10 | Q19: =D19-(1-F19)*E19-0.8*H20-0.5*G20 -> 0
A21: 10 | B21: فهرست بهای رشته ابنیه | C21: 108505072511 | D21: 86804058009 | F21: 0.2 | G21: 9 | H21: 28 | Q21: =D21-(1-F21)*E21-0.8*H22-0.5*G22 -> 84041990713
H22: 3452584120
A23: 11 | B23: فهرست بهای رشته آبياری و زهكشی | F23: 0.2 | G23: 8 | H23: 15 | Q23: =D23-(1-F23)*E23-0.8*H24-0.5*G24 -> 0
A25: 12 | B25: فهرست بهای رشته ساخت و ترميم قنات | F25: 0.2 | G25: 7 | H25: 11 | Q25: =D25-(1-F25)*E25-0.8*H26-0.5*G26 -> 0
A27: 13 | B27: فهرست بهای رشته تأسيسات برقی | F27: 0.2 | Q27: =0.5*(D27-E27)+F27*E27 -> 0
A29: 14 | B29: فهرست بهای رشته تأسيسات مكانيكی | F29: 0.2 | Q29: =0.5*(D29-E29)+F29*E29 -> 0
A31: 15 | B31: فهرست بهای رشته آبياری تحت فشار | F31: 0.2 | G31: 6 | H31: 7 | Q31: =D31-(1-F31)*E31-0.5*(G32+H32) -> 0
A33: 16 | B33: فهرست بهای رشته چاه | F33: 0.2 | Q33: =D33-(1-F33)*E33-0.8*(SUM(G34:P34)) -> 0
A35: 17 | B35: فهرست بها نگهداری ، تعمیر روسازی و ابنیه خطوط راه آهن سال | F35: 0.2 | Q35: =D35-(1-F35)*E35-0.8*(SUM(G36:P36)) -> 0
A37: 18 | B37: فهرست بها ترميم و بازسازی نوار حفاری در معابر شهری | F37: 0.2 | Q37: =D37-(1-F37)*E37-0.8*(SUM(G38:P38)) -> 0
A39: 19 | B39: مبلغ برآورد خرید تجهیزات خاص (سایر) | Q39: =D39-(1-F39)*E39-0.8*(SUM(G40:P40)) -> 0
A41: جمع کل مبلغ صورت وضعیت اصلاح شده فعلی با در نظر گرفتن مفاد بند 1-2-7-5 بخشنامه (ریال) | Q41: =SUM(Q3:Q40) -> 2.1226757e+11 | R41: انجام محاسبات
A42: جمع کل مبلغ صورت وضعیت اصلاح شده قبلی با در نظر گرفتن مفاد بند 1-2-7-5 بخشنامه (ریال) | Q42: 1.9947692e+11 | R42: جمع کل مبلغ صورت وضعیت اصلاح شده قبلی با در نظر گرفتن مفاد بند 1-2-7-5 بخشنامه وارد کنید
A43: کارکرد ماهانه صورت وضعیت پیمانکار (تفاضل دو ردیف‌ فوق) (F) | Q43: =Q41-Q42 -> 1.2790649e+10 | R43: انجام محاسبات
C45: مبلغ صورت‌وضعیت تجمعی پیمانکار را متناسب با فهرست مورد استفاده وارد کنید. | D45: مبلغ صورت‌وضعیت تجمعی پیمانکار را متناسب با فهرست مورد استفاده و بدون ضرایب پیشنهادی پیمانکار وارد کنید. | E45: مبلغ خرید تجهیزات خاص در صورتی که موجود باشد وارد کنید. | F45: مطابق با الگوی بند 1-2-7-5 و توافق طرفین | G45: با توجه به خلاصه مالی صورت وضعیت مبلغ هر یک فصول جدول را وارد کنید | Q45: انجام محاسبات

Sheet 1 خلاصه مالی صورت‌حساب
A1: جدول راهنمای تهیه صورتحساب خدمات نظارت بر پروژه « احداث ... »
A2: صورت حساب شماره : | E2: دوره کارکرد : 1403/01/01 تا 1403/01/31 | H2: کارفرما : | J2: پیمانکار : | L2: مشاور : | R2: شماره قرارداد : | X2: صفحه 1 از 5
A4: شماره فصل | B4: شرح فصل | H4: مبلغ مطابق قرارداد (ریال) | I4: مبلغ تجمعی تایید شده تا ماه گذشته | J4: وضعیت | L4: کارکرد دوره جاری (ریال) | R4: مبلغ به حروف (ریال)
A5: 2 | B5: خدمات نظارت در دوره قبل از اجرا | H5: 856922400 | I5: 785855420 | J5: درخواستی مشاور | L5: 0 | R5: صفر
H6: 856922400 | J6: تاییدشده کارفرما | L6: 0 | R6: صفر
A7: 3 | B7: حین اجرا | C7: خدمات نظارت ماهانه حین اجرا (فنی و پشتیبانی دفتر مرکزی) | H7: 4984321050 | I7: 3987456840 | J7: درخواستی مشاور | L7: ='4 پرداخت ماهانه و کارگاهی'!H7 -> 3.0201439e+08 | R7: دویست و بیست و نه میلیون وششصد و نوزده هزار و نهصد و هفده ریال
H8: 3987456840 | J8: تاییدشده کارفرما
C9: خدمات نظارت موردی حین اجرا (فنی و پشتیبانی دفتر مرکزی) | H9: 846607000 | I9: 539361408 | J9: درخواستی مشاور | L9: 0 | R9: صفر
H10: 677285600 | J10: تاییدشده کارفرما | L10: 0 | R10: صفر
C11: خدمات فنی کارگاهی | H11: 14346307530 | I11: 1.1477046e+10 | J11: درخواستی مشاور | L11: ='4 پرداخت ماهانه و کارگاهی'!H10 -> 1.8727208e+09 | R11: هشتصد و شش میلیون و هشتصد و پنجاه و یک هزار وهفتصد وسی و دو ریال
H12: 1.2032387e+10 | J12: تاییدشده کارفرما
A13: 4 | B13: بعد از اجرا | H13: 454840100 | I13: 0 | J13: درخواستی مشاور | L13: 0 | R13: صفر
H14: 454840100 | J14: تاییدشده کارفرما | L14: 0 | R14: صفر
A15: 5 | B15: پشتیبانی | H15: 70000000 | I15: 70000000 | J15: درخواستی مشاور | L15: ='5 پرداخت پشتیبانی'!Q13 -> 0 | R15: صفر
H16: 70000000 | J16: تاییدشده کارفرما | L16: 0 | R16: صفر
A17: جمع کل حق الزحمه (ریال) | H17: 21558998080 | I17: =I5+I7+I9+I11+I13+I15 -> 1.685972e+10 | J17: درخواستی مشاور | L17: =L5+L7+L9+L11+L13+L15 -> 2.1747352e+09 | R17: یك میلیارد وسی و شش میلیون و چهارصد و هفتاد و یک هزار و ششصد و چهل و نه ریال
J18: تاییدشده کارفرما | L18: =L6+L8+L10+L12+L14+L16 -> 0 | R18: صفر
A19: هزینه تعدیل
A20: * تمامی مبالغ در صورتحساب مشاور به ریال می‌باشد.

Sheet 2 خدمات ماهانه حین اجرا 
A1: جدول شماره 1 : محاسبه حق الزحمه خدمات ماهانه حین اجرا (فنی و پشتیبانی دفتر مرکزی) | F1: ='1 خلاصه مالی صورت‌حساب'!E2 -> دوره کارکرد : 1403/01/01 تا 1403/01/31 | O1: خدمات ارائه شده است
F2: ='1 خلاصه مالی صورت‌حساب'!A2 -> صورت حساب شماره : | O2: خدمات ارائه نشده است
F3: صفحه 2 از 5
A4: حق‌الزحمه خدمات نظارت ماهانه حین اجرا | I4: صورتحساب را بر اساس تحویل‌شدنی‌های ارائه شده به کارفرما محاسبه کنید.
A5: شماره ردیف | B5: نام ردیف | C5: تحویل‌شدنی | D5: چک لیست ارائه تحویل شدنی به کارفرما | E5: بهای پایه واحد نظارت | F5: ضریب اصلاح | G5: ضریب ویژگی | H5: بهای نظارت
H6: (ریال)
A7: 301010000 | B7: مدیریت و برنامه‌ریزی منابع و زمان
A8: 301010100 | B8: مدیریت منابع
A9: 301010101 | B9: تحلیل، بررسی و اظهارنظر در مورد جریان مالی پروژه | C9: گزارش ماهانه | D9: خدمات ارائه شده است | E9: 3300000 | F9: 0.62 | G9: 1.25 | H9: =IF(D9="خدمات ارائه شده است",E9*F9*G9,0) -> 2557500
A10: 301010102 | B10: بررسی و تأیید فهرست نیروی انسانی مدیریت فنی موردنیاز اجرای کار | C10: گزارش ماهانه | D10: خدمات ارائه شده است | E10: 6800000 | F10: 0.62 | G10: =G$9 -> 1.25 | H10: =IF(D10="خدمات ارائه شده است",E10*F10*G10,0) -> 5270000
A11: 301010103 | B11: بررسی،کنترل و اظهارنظر ماهانه ماشین‌آلات، نیروی انسانی، تجهیزات و مصالح | C11: گزارش ماهانه | D11: خدمات ارائه شده است | E11: 6800000 | F11: 0.62 | G11: =G$9 -> 1.25 | H11: =IF(D11="خدمات ارائه شده است",E11*F11*G11,0) -> 5270000
A12: 301010104 | B12: کنترل و پیگیری فعالیت‌های تدارک مصالح، تجهیزات و ماشین‌آلات | C12: گزارش ماهانه | D12: خدمات ارائه شده است | E12: 6800000 | F12: 0.62 | G12: =G$9 -> 1.25 | H12: =IF(D12="خدمات ارائه شده است",E12*F12*G12,0) -> 5270000
A13: 301010105 | B13: بررسی و تحلیل کنترل ورود و خروج مواد، مصالح، تجهیزات و ماشین‌آلات | C13: گزارش ماهانه | D13: خدمات ارائه شده است | E13: 6800000 | F13: 0.62 | G13: =G$9 -> 1.25 | H13: =IF(D13="خدمات ارائه شده است",E13*F13*G13,0) -> 5270000
A14: 301010200 | B14: مدیریت زمان
A15: 301010201 | B15: تهیه جدول یا ساختار شکست نمایش‌دهنده میزان پیشرفت واقعی و برنامه‌ریزی‌شده در آن‌ماه | C15: گزارش ماهانه | D15: خدمات ارائه شده است | E15: 8400000 | F15: 0.62 | G15: =G$9 -> 1.25 | H15: =IF(D15="خدمات ارائه شده است",E15*F15*G15,0) -> 6510000
A16: 301010202 | B16: تعیین و رتبه‌بندی فعالیت‌های دارای تأخیر بر اساس معیارهای زمان، هزینه، بحرانی‌بودن و پیچیدگی | C16: گزارش ماهانه | D16: خدمات ارائه شده است | E16: 6800000 | F16: 0.62 | G16: =G$9 -> 1.25 | H16: =IF(D16="خدمات ارائه شده است",E16*F16*G16,0) -> 5270000
A17: 301010203 | B17: تحلیل تأخیر فعالیت‌های دارای اهمیت بالا و ارائه راهکارها جهت جبران یا مدیریت این تأخیرها | C17: گزارش ماهانه | D17: خدمات ارائه شده است | E17: 6800000 | F17: 0.62 | G17: =G$9 -> 1.25 | H17: =IF(D17="خدمات ارائه شده است",E17*F17*G17,0) -> 5270000
A18: 301010204 | B18: ارائه محاسبات مربوط به میزان تأخیرهای مجاز و غیرمجاز | C18: گزارش ماهانه | D18: خدمات ارائه شده است | E18: 6800000 | F18: 0.62 | G18: =G$9 -> 1.25 | H18: =IF(D18="خدمات ارائه شده است",E18*F18*G18,0) -> 5270000
A19: 301010205 | B19: ارائه محاسبات و پیش‌بینی‌های ارزش کسب‌شده و ارائه راهکارهای افزایش ارزش‌کسب‌شده | C19: گزارش ماهانه | D19: خدمات ارائه شده است | E19: 6800000 | F19: 0.62 | G19: =G$9 -> 1.25 | H19: =IF(D19="خدمات ارائه شده است",E19*F19*G19,0) -> 5270000
A20: 301020000 | B20: خدمات مدیریت پروژه، هماهنگی و یکپارچگی
A21: 301020100 | B21: تهیه گزارش یکپارچگی مدیریت پروژه (بررسی اثر تغییرات هر حوزه بر حوزه‌های دیگر و بر زمان، هزینه و کیفیت پروژه) | C21: گزارش ماهانه | D21: خدمات ارائه شده است | E21: 41900000 | F21: 0.62 | G21: =G$9 -> 1.25 | H21: =IF(D21="خدمات ارائه شده است",E21*F21*G21,0) -> 32472500
A22: 301020200 | B22: تهیه گزارش تغییرات کارهای انجام‌شده (زمان، هزینه و کیفیت) | C22: گزارش ماهانه | D22: خدمات ارائه شده است | E22: 41900000 | F22: 0.62 | G22: =G$9 -> 1.25 | H22: =IF(D22="خدمات ارائه شده است",E22*F22*G22,0) -> 32472500
A23: 301020300 | B23: تهیه گزارش تطبیق تصمیمات دستگاه اجرایی و مشاور با اسناد و مدارک پیمان | C23: گزارش ماهانه | D23: خدمات ارائه شده است | E23: 21800000 | F23: 0.62 | G23: =G$9 -> 1.25 | H23: =IF(D23="خدمات ارائه شده است",E23*F23*G23,0) -> 16895000
A24: 301020400 | B24: تهیه گزارش برگزاری جلسات پیشبرد پروژه با ارکان پروژه و ارائه سناریوهای مختلف ادامه پروژه | C24: گزارش به انضمام صورت‌جلسات پیشبرد اهداف کمی و کیفی پروژه | D24: خدمات ارائه شده است | E24: 77000000 | F24: 0.62 | G24: =G$9 -> 1.25 | H24: =IF(D24="خدمات ارائه شده است",E24*F24*G24,0) -> 59675000
A25: 301020500 | B25: پیگیری دستمزد کارگران پیمانکار | C25: گزارش | D25: خدمات ارائه شده است | E25: 8400000 | F25: 0.62 | G25: =G$9 -> 1.25 | H25: =IF(D25="خدمات ارائه شده است",E25*F25*G25,0) -> 6510000
A26: 301020600 | B26: بررسی مطالبات پیمانکاران جزء | C26: گزارش | D26: خدمات ارائه شده است | E26: 8400000 | F26: 0.62 | G26: =G$9 -> 1.25 | H26: =IF(D26="خدمات ارائه شده است",E26*F26*G26,0) -> 6510000
A27: 301030000 | B27: خدمات کنترل کیفیت
A28: 301030100 | B28: بررسی صحت کارهای انجام‌شده از لحاظ کمی و کیفی (صورت‌جلسات، برگ‌های آزمایشگاهی، گواهی‌های انجام کار، خدمات بازرسی، کنترل کیفیت و کمیت مصالح وارده به کارگاه) | C28: گزارش ماهانه صورت‌جلسات شیت‌های آزمایشگاهی و گواهی‌های انجام کار | D28: خدمات ارائه شده است | E28: 26900000 | F28: 0.62 | G28: =G$9 -> 1.25 | H28: =IF(D28="خدمات ارائه شده است",E28*F28*G28,0) -> 20847500
A29: 301030200 | B29: بررسی و تحلیل تغییر شکل‌ها و کنترل رواداری‌های مجاز | C29: گزارش | D29: خدمات ارائه شده است | E29: 13300000 | F29: 0.62 | G29: =G$9 -> 1.25 | H29: =IF(D29="خدمات ارائه شده است",E29*F29*G29,0) -> 10307500
A30: 301030300 | B30: دستور اصلاح کارهای معیوب و نظارت بر فرآیند رفع آن‌ها | C30: مکاتبه و گزارش ماهانه | D30: خدمات ارائه شده است | E30: 13300000 | F30: 0.62 | G30: =G$9 -> 1.25 | H30: =IF(D30="خدمات ارائه شده است",E30*F30*G30,0) -> 10307500
A31: 301030400 | B31: رسیدگی، اعلام نظر و تأیید نقشه‌های کارگاهی تهیه‌شده به‌وسیله پیمانکار | C31: گزارش ماهانه | D31: خدمات ارائه شده است | E31: 13300000 | F31: 0.62 | G31: =G$9 -> 1.25 | H31: =IF(D31="خدمات ارائه شده است",E31*F31*G31,0) -> 10307500
A32: 301030500 | B32: بررسی و تایید نقشه‌های چون‌ساخت تهیه‌شده به‌وسیله پیمانکار و تأیید آن‌ها | C32: گزارش ماهانه | D32: خدمات ارائه شده است | E32: 20100000 | F32: 0.62 | G32: =G$9 -> 1.25 | H32: =IF(D32="خدمات ارائه شده است",E32*F32*G32,0) -> 15577500
A33: 301040000 | B33: مالی و قراردادی
A34: 301040100 | B34: بررسی و تأیید صورت‌وضعیت‌های ماهانه پیمانکار(اعم از کارکرد ماهانه، تعدیل و غیره) با در نظر گرفتن تمام ضوابط، مقررات و دستورالعمل های مربوط | C34: صورت‌وضعیت تأییدشده توسط مهندس مشاور | D34: خدمات ارائه شده است | E34: 32500000 | F34: 0.62 | G34: =G$9 -> 1.25 | H34: =IF(D34="خدمات ارائه شده است",E34*F34*G34,0) -> 25187500
A35: 301050000 | B35: ایمنی و محیط‌زیست
A36: 301050100 | B36: پیگیری و بررسی وضعیت رعایت دستورالعمل‌های ایمنی، امنیت، بهداشت و محیط زيست (HSSE) درکارگاه | C36: گزارش ماهانه | D36: خدمات ارائه شده است | E36: 13300000 | F36: 0.62 | G36: =G$9 -> 1.25 | H36: =IF(D36="خدمات ارائه شده است",E36*F36*G36,0) -> 10307500
A37: 301060000 | B37: مدیریت ریسک
A38: 301060100 | B38: تهیه گزارش تحلیلی ریسک‌های پروژه و پیامدهای مثبت و منفی آن | C38: گزارش ماهانه | D38: خدمات ارائه شده است | E38: 35100000 | F38: 0.62 | G38: =G$9 -> 1.25 | H38: =IF(D38="خدمات ارائه شده است",E38*F38*G38,0) -> 27202500
A39: 301070000 | B39: مدیریت ارتباطات
A40: 301070100 | B40: تهیه بایگانی موضوعی به صورت ماهانه (مستندسازی) | C40: ارائه فایل آرشیو | D40: خدمات ارائه شده است | E40: 13300000 | F40: 0.62 | G40: =G$9 -> 1.25 | H40: =IF(D40="خدمات ارائه شده است",E40*F40*G40,0) -> 10307500
...

Sheet 3 خدمات فنی کارگاهی
A2: جدول شماره 2 : محاسبه حق‏الزحمه عوامل فنی و تردد کارگاهی پروژه «احداث ...» | V2: ='1 خلاصه مالی صورت‌حساب'!E2 -> دوره کارکرد : 1403/01/01 تا 1403/01/31
V3: ='1 خلاصه مالی صورت‌حساب'!A2 -> صورت حساب شماره :
V4: صفحه 3 از 5
A5: شماره ردیف | B5: طبقه شغلی | C5: رتبه | D5: تعداد | F5: سرپرست عوامل فنی و کارگاهی | G5: حق الزحمه سرپرست عوامل فنی کارگاهی با اعمال شبکاری، ضریب منظقه ای، ضریب ویژگی و ضریب تردد | H5: بهای پایه نظارت (ریال) | L5: مجموع ساعات کارکرد روز | N5: مجموع ساعات کارکرد شب‌ | P5: حق‌الزحمه (ریال) | Y5: زمان و تعداد هر یک از عوامل را متناسب با رتبه و طبقه شغلی در جدول وارد نمائید.
P6: عادی ماهانه | S6: شبکاری | U6: ضریب منطقه ای (r) | V6: ضریب ویژگی کار | W6: جمع (ریال)
A7: 303010000 | B7: 1 | C7: 5 | D7: 0 | F7: 0 | G7: =F7*W7*$W$18 -> 0 | H7: 1795000 | P7: =L7*H7 -> 0 | S7: =1.4*N7*H7 -> 0 | U7: 1.6 | V7: 1.25 | W7: =(P7+S7)*U7*V7 -> 0
A8: 303020000 | B8: 1 | C8: 4 | D8: 1 | F8: 0 | G8: =F8*W8*$W$18 -> 0 | H8: 1912000 | I8: 403 | J8: 403 | K8: 403 | P8: =L8*H8 -> 0 | S8: =1.4*N8*H8 -> 0 | U8: 1.6 | V8: 1.25 | W8: =(P8+S8)*U8*V8 -> 0 | Y8: ا
A9: 303030000 | B9: 1 | C9: 3 | D9: 2 | F9: 0 | G9: =F9*W9*$W$18 -> 0 | H9: 2149000 | I9: 453 | J9: 453 | K9: 453 | L9: 0 | P9: =L9*H9 -> 0 | S9: =1.4*N9*H9 -> 0 | U9: 1.6 | V9: 1.25 | W9: =(P9+S9)*U9*V9 -> 0
A10: 303040000 | B10: 1 | C10: 2 | D10: 0 | F10: 0 | G10: =F10*W10*$W$18 -> 0 | H10: 2499000 | I10: 526 | J10: 526 | K10: 526 | L10: 200 | P10: =L10*H10 -> 499800000 | S10: =1.4*N10*H10 -> 0 | U10: 1.6 | V10: 1.25 | W10: =(P10+S10)*U10*V10 -> 999600000
A11: 303050000 | B11: 1 | C11: 1 | D11: 1 | F11: 1 | G11: =F11*W11*$W$18 -> 1578444000 | H11: 2967000 | I11: 625 | J11: 625 | K11: 625 | L11: 200 | P11: =L11*H11 -> 593400000 | S11: =1.4*N11*H11 -> 0 | U11: 1.6 | V11: 1.25 | W11: =(P11+S11)*U11*V11 -> 1186800000
A12: 303060000 | B12: 2 | C12: 5 | D12: 0 | F12: 0 | G12: =F12*W12*$W$18 -> 0 | H12: 1445000 | I12: 305 | J12: 305 | K12: 305 | L12: 0 | P12: =L12*H12 -> 0 | S12: =1.4*N12*H12 -> 0 | U12: 1.6 | V12: 1.25 | W12: =(P12+S12)*U12*V12 -> 0
A13: 303070000 | B13: 2 | C13: 4 | D13: 1 | F13: 0 | G13: =F13*W13*$W$18 -> 0 | H13: 1564000 | I13: 329 | J13: 329 | K13: 329 | L13: 0 | P13: =L13*H13 -> 0 | S13: =1.4*N13*H13 -> 0 | U13: 1.6 | V13: 1.25 | W13: =(P13+S13)*U13*V13 -> 0
A14: 303080000 | B14: 2 | C14: 3 | D14: 0 | F14: 0 | G14: =F14*W14*$W$18 -> 0 | H14: 1718000 | I14: 329 | J14: 329 | K14: 329 | L14: 0 | P14: =L14*H14 -> 0 | S14: =1.4*N14*H14 -> 0 | U14: 1.6 | V14: 1.25 | W14: =(P14+S14)*U14*V14 -> 0
A15: 303090000 | B15: 2 | C15: 2 | D15: 0 | F15: 0 | G15: =F15*W15*$W$18 -> 0 | H15: 1989000 | I15: 329 | J15: 329 | K15: 329 | L15: 0 | P15: =L15*H15 -> 0 | S15: =1.4*N15*H15 -> 0 | U15: 1.6 | V15: 1.25 | W15: =(P15+S15)*U15*V15 -> 0
A16: 303100000 | B16: 2 | C16: 1 | D16: 0 | F16: 0 | G16: =F16*W16*$W$18 -> 0 | H16: 2226000 | I16: 329 | J16: 329 | K16: 329 | L16: 0 | P16: =L16*H16 -> 0 | S16: =1.4*N16*H16 -> 0 | U16: 1.6 | V16: 1.25 | W16: =(P16+S16)*U16*V16 -> 0
A17: جمع کارکرد عوامل | W17: =SUM(W7:X16) -> 2186400000
A18: ضریب تردد کارگاهی طبق قرارداد (K) | W18: 1.33
A19: جمع حق الزحمه ماهانه خدمات فنی کارگاهی ( ) | W19: =W17*W18 -> 2907912000
A20: در این جدول نیازی به نوشتن نام و نام خانوادگی عوامل نمی‌باشد و نام و نام خانوادگی عوامل در پیوست رتبه و طبقه شغلی درج شود.
L24: جمع هزینه‌های پشتیبانی (دستگاه‏ها و تجهیزات نقشه‏برداری) (جدول 3):
L25: جمع هزینه‌های پشتیبانی (هزینه محل کار و سکونت) (جدول 4):

Sheet رتبه و طبقه شغلی
A1: جدول معرفی رتبه و طبقه شغلی عوامل (پیوست جدول شماره2) | G1: ='1 خلاصه مالی صورت‌حساب'!E2 -> دوره کارکرد : 1403/01/01 تا 1403/01/31
G2: ='1 خلاصه مالی صورت‌حساب'!A2 -> صورت حساب شماره :
A3: ردیف | B3: نام و نام خانوادگی | C3: سمت درکارگاه | D3: تاریخ معرفی و یا اولین حضور در پروژه | E3: طبقه شغلی | F3: رتبه شغلی | G3: تعداد روزهاي كاري | H3: كل ساعات كاركرد طبق زمان برگ
A4: 1 | C4: سرپرست عوامل فنی کارگاهی | D4: 1402/02/20 | E4: 1 | F4: 1 | G4: 20 | H4: 150
A5: 2 | C5: ناظر سیویل | D5: 1402/02/21 | E5: 1 | F5: 3 | G5: 15 | H5: 120
A6: 3 | C6: ناظر تاسیسات مکانیکی | D6: 1402/03/14 | E6: 1 | F6: 3 | G6: 22 | H6: 176
A7: 4 | C7: ناظر تاسیسات برق | D7: 1402/04/01 | E7: 1 | F7: 4 | G7: 23 | H7: 176
A8: 5 | C8: نقشه بردار | D8: 1402/04/01 | E8: 2 | F8: 4 | G8: 23 | H8: 176
A9: بر اساس بند 3-3-2-2-2 بخشنامه حداکثر ساعت کاری هر یک از عوامل 250 ساعت می‌باشد.
A10: این پیوست صرفا جهت اطلاع‌رسانی به کارفرما ارائه می‌شود

Sheet 4 پرداخت ماهانه و کارگاهی
B2: 1 | C2: 2 | D2: 3 | E2: 4 | F2: 5 | G2: 6 | H2: 7
B3: مبلغ پيمان ( C ) با در نظر گرفتن مفاد بند 1-2-7-5 بخشنامه(ريال) | C3: سقف نصاب معاملات کوچک (ریال) | D3: برآورد کل حق الزحمه نظارت ماهانه حین اجراي مشاور بر اساس قرارداد (Ba) | E3: برآورد کل حق الزحمه نظارت فنی کارگاهی در قرارداد (Bb) | F3: q | G3: r | H3: k
B4: 250000000000 | C4: 1450000000 | D4: 5434920000 | E4: 17129022390 | F4: 1.25 | G4: 1.6 | H4: 1.33
B5: محاسبه و پرداخت حق‏الزحمه خدمات ماهانه حین اجرا (ریال)
B6: جمع کل مبلغ صورت وضعیت اصلاح شده فعلی با در نظر گرفتن مفاد بند 1-2-7-5 بخشنامه | C6: جمع کل مبلغ صورت وضعیت اصلاح شده قبلی با در نظر گرفتن مفاد بند 1-2-7-5 بخشنامه | D6: کارکرد ماهانه صورت وضعیت پیمانکار (تفاضل ردیف‌های 3و4) (F) | E6: پیشرفت ماهانه پروژه | F6: برآورد حق‌الزحمه بر اساس پیشرفت ماهانه پروژه | G6: حق الزحمه ماهانه کارکرد مشاور (Ea) | H6: حق الزحمه درخواستی مشاور موضوع بند 3-1-3 (ریال)
B7: ='ورودی محاسبات صورت وضعیت'!Q41 -> 2.1226757e+11 | C7: ='ورودی محاسبات صورت وضعیت'!Q42 -> 1.9947692e+11 | D7: =B7-C7 -> 1.2790649e+10 | E7: =ROUND(D7/B4,4) -> 0.0512 | F7: =E7*D$4 -> 278267904 | G7: ='2 خدمات ماهانه حین اجرا '!G41 -> 346115000 | H7: =IF(G7>F7,F7+0.35*(G7-F7),G7+0.35*(F7-G7)) -> 3.0201439e+08
B8: محاسبه و پرداخت حق‏الزحمه خدمات فنی کارگاهی (ریال)
B9: جمع کل مبلغ صورت وضعیت اصلاح شده فعلی با در نظر گرفتن مفاد بند 1-2-7-5 بخشنامه | C9: جمع کل مبلغ صورت وضعیت اصلاح شده قبلی با در نظر گرفتن مفاد بند 1-2-7-5 بخشنامه | D9: کارکرد ماهانه صورت وضعیت پیمانکار (تفاضل ردیف‌های 3و4) (F) | E9: برآورد حق‌الزحمه بر اساس کارکرد ماهانه پروژه | G9: حق الزحمه ماهانه کارکرد مشاور (Eb) | H9: حق الزحمه درخواستی مشاور موضوع بند 4-3-3 (ریال)
B10: ='ورودی محاسبات صورت وضعیت'!Q41 -> 2.1226757e+11 | C10: ='ورودی محاسبات صورت وضعیت'!Q42 -> 1.9947692e+11 | D10: =B10-C10 -> 1.2790649e+10 | E10: =8*((D10/1000)^0.64)*F4*G4*H4*1.572*1000 -> 1.1825933e+09 | G10: ='3 خدمات فنی کارگاهی'!W19 -> 2907912000 | H10: =MAX(IF(E10>2*C4,IF(G10>=E10,IF(G10<3.5*E10,E10+0.4*(G10-E10),2*E10),IF(G10<0.5*E10,G10,G10+0.4*(E10-G10))),IF(G10>=E10,E10+0.4*(G10-E10),IF(G10<0.5*E10,G10,G10+0.4*(E10-G10)))),SUM('3 خدمات فنی کارگاهی'!G7:G16)) -> 1.8727208e+09

Sheet 5 پرداخت پشتیبانی
A1: جدول محاسبه هزینه های پشتیانی پروژه « احداث ...» | L1: ='1 خلاصه مالی صورت‌حساب'!E2 -> دوره کارکرد : 1403/01/01 تا 1403/01/31
L2: ='1 خلاصه مالی صورت‌حساب'!A2 -> صورت حساب شماره :
L3: صفحه 5 از 5
A4: شماره ردیف | B4: نام ردیف | H4: بهای پایه نظارت | L4: تعداد | P4: جمع کل حق‏الزحمه (ریال)
A5: 501010000 | B5: هزینه ماهانه توتال استیشن با دقت 5 ثانیه و متعلقات مربوط | H5: 124500000 | L5: 0 | P5: =H5*L5 -> 0 | S5: تعداد دستگاه‌ها و تجهیزات را وارد نمائید
A6: 501020000 | B6: هزینه ماهانه دوربین ترازیاب دیجیتال و متعلقات مربوط | C6: 2 | H6: 31100000 | L6: 0 | P6: =H6*L6 -> 0 | S6: تعداد دستگاه‌ها و تجهیزات را وارد نمائید
A7: 501030000 | B7: هزینه روزانه استفاده از دستگاه GPS دو یا سه فرکانس | C7: 3 | H7: 15100000 | L7: 0 | P7: =H7*L7 -> 0 | S7: تعداد دستگاه‌ها و تجهیزات را وارد نمائید
A8: 501040000 | B8: هزینه خرید دستگاه حضور و غیاب و نصب و پلمپ آن | C8: 4 | H8: 231100000 | L8: 0 | P8: =H8*L8 -> 0 | S8: هزینه و تعداد مورد نیاز را وارد نمائید
A9: 501050000 | B9: هزینه تامین و تجهیز دفتر کار* | C9: 5 | H9: 0 | L9: 0 | P9: =H9*L9 -> 0 | S9: هزینه و تعداد مورد نیاز را وارد نمائید
A10: 501060000 | B10: هزینه تامین و تجهیز محل سکونت* | C10: 1 | H10: 0 | L10: 0 | P10: =H10*L10 -> 0 | S10: هزینه و تعداد مورد نیاز را وارد نمائید
A11: 501070000 | B11: هزینه غذا* | C11: 2 | H11: 0 | L11: 0 | P11: =H11*L11 -> 0 | S11: هزینه و تعداد مورد نیاز را وارد نمائید
A12: 501080000 | B12: هزینه بهره‌برداری و نگهداری دفاتر کار و محل سکونت* | C12: 3 | H12: 0 | L12: 0 | P12: =H12*L12 -> 0 | S12: هزینه و تعداد مورد نیاز را وارد نمائید
A13: جمع هزینه های ماهانه پشتیبانی (ریال): | P13: =SUM(P5:R12) -> 0
